Workbook

Sheet Read me
A1: AI-detection screen of the 2026 Arizona Voter Education Guide
A2: Prepared by Luke Basler
A4: What this is
A5: I screened every candidate statement in the Arizona Citizens Clean Elections Commission's 2026 General
A6: Election Voter Education Guide for AI-generated text with Pangram 4.0.
A7: 208 candidates appear in the guide and 198 submitted a statement.
A9: What the AI score means
A10: Pangram returns 'fraction_ai': the share of the statement it attributes to a language model,
A11: from 0.00 (no text classified as AI-generated; AI-assisted text may still be present) to 1.00 (entirely AI) - that is column I in the "Candidates" tab. Column J is Pangram's own three-way label.
A12: A statement is counted as FLAGGED here when the AI score is above 0.50. That threshold is
A13: mine, not Pangram's.
A15: Reported accuracy
... A22: Because there are so few Green, Independent and No Labels statements, comparisons involving them are likely not statistically significant.

Sheet Candidates
A1: Candidate | B1: Party | C1: Office | D1: District | E1: Race type | F1: Chamber | G1: PDF page (printed page + 2) | H1: Words | I1: Pangram AI score | J1: Pangram label | K1: Flagged (>0.50) | L1: Statement
A2: Kris Mayes | B2: Democratic | C2: Attorney General | E2: Statewide | G2: 26 | H2: 194 | I2: 0 | J2: Human | K2: =IF(I2="","no statement",IF(I2>0.5,"Yes","No")) -> No | L2: I have fought like hell for Arizonans protecting seniors from scams and abuse, stopping the flow of deadly fentanyl, lowering prices, blocking mega-mergers, and addressing rising rent. By working with local police, sheriffs, and federal partners, I have seized 27 million pills of fentanyl and protected Arizonans from drug smugglers and scammers. To defend our groundwater, I sued a Saudi-owned mega farm for excessive groundwater pumping harming rural neighbors and ranchers. I blocked the Albertson and Kroger merger preventing job loss, higher grocery prices, and exacerbated food deserts.I have intervened against APS and TEP’s unfair 14% rate hike and cracked down on billions in Medicaid fraud, successfully reducing fraudulent billing by 92%. My federal lawsuits have saved Arizonans $1.5 billion in taxpayer dollars by protecting Headstart, Meals on Wheels, and Americorps. My record at the U.S Supreme Court on behalf of Arizona is 2-0, overturning illegal tariffs costing Arizonans an average $1,500 a year. As a daughter of rural Arizona, I have held over 50 town halls across all 15 counties. It’s critical to reelect me as your Attorney General, so I can keep protecting Arizona families and making life more affordable in Arizona.
A3: Warren Petersen | B3: Republican | C3: Attorney General | E3: Statewide | G3: 26 | H3: 197 | I3: 0 | J3: Human | K3: =IF(I3="","no statement",IF(I3>0.5,"Yes","No")) -> No | L3: I will restore the Attorney General’s Office to its mission: fighting crime, combatting fraud and corruption, and defending our Constitution. I am the only candidate endorsed by Arizona’s largest law enforcement organizations, making my opponent the first incumbent Attorney General to be rejected by law enforcement because of her explosive temper, soft-on-crime positions, and dangerous rhetoric towards officers. With more than a decade of legal experience, including prosecution, lawmaking, and serving as Judiciary and Rules Chairman, and Senate President, I have stepped in to manage more than 130 cases and amicus briefs when Mayes refused to defend Arizona laws. As the de facto AG, I successfully took Arizona’s Save Women’s Sports Act to the U.S. Supreme Court to keep men out of women’s sports. I have protected Arizonans from sex offenders and open borders when Mayes failed to act. Under Mayes, the office has become partisan and political, and while she blames others for rising prices, her extreme environmental votes as an Arizona Corporation Commissioner have driven up costs. Already leading a major branch of government, I have the legal experience, leadership, and judgment to be Attorney General on day one. I respectfully ask for your vote.
A4: Clara Pratte | B4: Democratic | C4: Corporation Commissioner | E4: Statewide | G4: 31 | H4: 179 | I4: 1 | J4: AI | K4: =IF(I4="","no statement",IF(I4>0.5,"Yes","No")) -> Yes | L4: I’m running for the Arizona Corporation Commission because I’ve lived the consequences of decisions made in this office. Growing up on the Navajo Nation without electricity or running water, I understand how essential reliable and affordable utilities are to everyday life. Today, too many Arizona families, ranging from rural communities to our cities, are struggling with rising costs and uncertainty about the future. I’ve spent my career working in energy, economic development, and now as a small business owner, helping bring infrastructure and opportunity to communities that have been overlooked. Communities just like my hometown. It's why I believe the Commission should be a watchdog for the people by ensuring fair rates, reliable service, and encouraging smart investments that strengthen our economy while protecting our air and water. We can expand clean, cost-effective energy, create good-paying jobs, and protect our natural resources while keeping Arizona competitive. We just need the political courage to do so. I’m running to fight for affordable utility bills, limit data centers, and protect our water. I hope to have the honor of your vote.
A5: Jonathon Hill | B5: Democratic | C5: Corporation Commissioner | E5: Statewide | G5: 30 | H5: 146 | I5: 1 | J5: AI | K5: =IF(I5="","no statement",IF(I5>0.5,"Yes","No")) -> Yes | L5: I’m running for the Arizona Corporation Commission because too many Arizonans are paying more every month and seemingly getting less in return. As a scientist who has spent my career working on complex systems and solving real-world problems, I believe we need leadership that is grounded in facts, transparency, and accountability. The Commission has enormous influence over our utility bills, our energy reliability, and our long-term economic competitiveness, yet too often it has failed to ask tough questions or fully represent ratepayers. I’m not running as a career politician; I’m running as someone who believes government should work for people, not special interests. We can lower costs, strengthen our grid, and invest in cleaner, more efficient energy that protects our water and air while supporting business growth. Arizona deserves leadership that is practical, forward-thinking, and focused on results. That’s what I will bring to the Commission.
A6: Kevin Thompson | B6: Republican | C6: Corporation Commissioner | E6: Statewide | G6: 31 | H6: 199 | I6: 0 | J6: Human | K6: =IF(I6="","no statement",IF(I6>0.5,"Yes","No")) -> No | L6: One office that shouldn’t be political is the regulators who oversee utilities and our grid. My focus is protecting ratepayers and grid stability. I’ve championed an all-of-the above energy approach to manage Arizona’s energy grid, focusing on eliminating Green New Deal policies that have cost customers billions of dollars in extra surcharges, while pushing for greater ratepayer protections and holding utilities accountable for wasteful and frivolous spending. I championed the elimination of previously enacted Commission mandates that forced utilities to fund energy projects and programs costing ratepayers nearly $4Billion since their inception. I led the charge in eliminating over $50Million in ratepayer surcharges from the state’s largest electric utility in incentives for things like electric golf carts, EV charging stations, and payments to homebuilders to install appliances. I’ve worked tirelessly to remove regulatory barriers and mandates to unleash energy innovation, while ensuring grid stability and maintaining reliable energy supply. Under my watch, Arizona’s grid is now ranked the 7th most reliable in the country. I recently led the charge to prevent ratepayers from being saddled with $1.9Billion in extra costs to open a shuttered power plant and have worked on federal permitting reform for natural gas and nuclear power.
A7: Mike Cease | B7: Green | C7: Corporation Commissioner | E7: Statewide | G7: 30 | J7: no statement | K7: =IF(I7="","no statement",IF(I7>0.5,"Yes","No")) -> no statement | L7: (none submitted)
A8: Ralph Heap | B8: Republican | C8: Corporation Commissioner | E8: Statewide | G8: 30 | H8: 162 | I8: 1 | J8: AI | K8: =IF(I8="","no statement",IF(I8>0.5,"Yes","No")) -> Yes | L8: Ralph Heap was elected to the Arizona House of Representatives, where he has been a strong voice for limited government, free markets, medical freedom, and parental rights. Now, as a candidate for the Arizona Corporation Commission, Dr. Heap is ready to stand up for ratepayers, defend rural communities, and block the encroachment of globalist energy agendas. As Corporation Commissioner, Dr. Heap will: • Fight against ESG mandates and California-style energy experiments • Oppose unnecessary utility rate increases that punish families and seniors • Ensure a reliable, diverse energy grid — not one dictated by ideology • Fully Support the Trump Energy Agenda, with emphasis on fossil fuels and Nuclear energy. • • Protect water access and infrastructure, especially in rural Arizona • Demand transparency and stand against special interest influence at the Commission With decades of real-world experience, a commitment to constitutional principles, and a heart for service, Dr. Ralph Heap is the steady, conservative leader Arizona needs at the Corporation Commission.
A9: Andy Biggs | B9: Republican | C9: Governor | E9: Statewide | G9: 20 | H9: 95 | I9: 0 | J9: Human | K9: =IF(I9="","no statement",IF(I9>0.5,"Yes","No")) -> No | L9: Andy Biggs is running for Governor to bring down costs for Arizona families and businesses by growing our economy, lowering taxes, encouraging job growth, and reducing government interference. As Governor, he will prioritize the use and expansion of reliable and affordable energy sources for every Arizonan and responsibly manage our water and land resources to ensure long-term growth and an increased supply of single-family homes. Biggs will protect the rights and freedoms of Arizonans to make their own education and health choices, supporting school choice policies and enacting the MAHA agenda at the state level.
A10: Katie Hobbs | B10: Democratic | C10: Governor | E10: Statewide | G10: 20 | H10: 194 | I10: 0 | J10: Human | K10: =IF(I10="","no statement",IF(I10>0.5,"Yes","No")) -> No | L10: As governor, Katie Hobbs has put politics aside and focused on tackling the tough challenges facing Arizona. As Washington, D.C. policies raise costs on everything from healthcare to groceries to gas, Katie is fighting to make life more affordable for Arizona families. She passed middle-class tax cuts that save 88% of Arizonans money, give seniors an additional $6,000 deduction, and eliminate taxes on tips and overtime pay. She repealed the tax on rent, helped first-time homebuyers afford down payments, and cut red tape to make housing more affordable. While Washington politicians have slashed healthcare, Katie eliminated medical debt for nearly 700,000 Arizonans and lowered prescription drug costs by up to 80%. She stood up to her own party and the federal government to secure Arizona’s water and canceled leases allowing a Saudi-owned corporation to pump Arizona’s groundwater unchecked. She’s worked with law enforcement to seize over 18 million fentanyl pills, fight human trafficking, and combat cartels throughout Arizona. Katie knows there’s more work to do, and she’ll keep standing up to Washington and her own party to put Arizona first and fight to lower costs, keep communities safe, and create opportunity for every Arizonan.
A11: Risa Lombardo | B11: Green | C11: Governor | E11: Statewide | G11: 21 | H11: 197 | I11: 0 | J11: Human | K11: =IF(I11="","no statement",IF(I11>0.5,"Yes","No")) -> No | L11: Risa Lombardo is running for Governor because she knows families are struggling, and Katie Hobbs and the Republicans are too busy squabbling to fix things. As Governor, Lombardo will transform our broken two -party system into a state government that serves the people, not greed or corporate interests. She will protect our fragile democracy from those who overstep their legal authority and from those who attack it to further their political ambitions. She will stop the Data Centers that Republican and Democrats are allowing to happen without proper consideration of the costs, water and energy demands involved. She will end the use of Flock Cameras to track Arizona residents’ every movement across the state as we merely drive through our communities. She will stop discrimination by race, class, gender, sexual orientation, age, nationality, or religion. She will combat Climate Change, protect our environment, and ensure policies that create clean air and clean water for Arizona residents. And she will reduce the costs of utilities for working families. Hobbs and the Republicans are too busy fighting to find common ground. Shatter this two-party system and change Arizona politics forever! Risa Lombardo would be honored to have your vote.
A12: Teri Ann Hourihan | B12: No Labels | C12: Governor | E12: Statewide | G12: 21 | H12: 193 | I12: 1 | J12: AI | K12: =IF(I12="","no statement",IF(I12>0.5,"Yes","No")) -> Yes | L12: Teri Ann chose to run as an Independent/No Labels candidate because she believes political division has prevented meaningful solutions and left too many Arizonans behind. She is committed to putting people before politics and leading with honesty, integrity, accountability, and common sense—not party agendas, special interests, or wealthy donors. Teri Ann has pledged never to accept PAC or AIPAC donations because she believes elected officials should be accountable to the people they serve. As Governor, she will restore public trust by reforming state government, increasing transparency, and ensuring agencies operate efficiently and responsibly. Her priorities include lowering the cost of living, protecting the rights of all people, expanding affordable childcare, protecting school choice while increasing accountability for education spending, securing Arizona's water future, reducing homelessness through shelter and support services, strengthening the family court system, supporting rural communities, improving legal immigration processes, and eliminating fraud, waste, and abuse in government. Above all, Teri Ann believes leadership begins with listening. She is committed to being accessible, accountable, and responsive to every Arizonan while delivering practical, bipartisan solutions that unite communities, restore trust in government, and improve the quality of life for families across Arizona.
A13: Angela Harrolle Mohan (Hourihan) | B13: Independent | C13: Lieutenant Governor | E13: Statewide | G13: 23 | H13: 163 | I13: 0.21130435 | J13: Mixed | K13: =IF(I13="","no statement",IF(I13>0.5,"Yes","No")) -> No | L13: Political: Angela is not a career politician but a citizen inspired to serve after witnessing the challenges facing everyday Arizonans. She believes government works best when leaders focus on practical solutions rather than partisan politics. She successfully championed bipartisan legislation signed into law.. A registered Independent, Angela has previously been registered as both a Democrat and Republican to participate in their primary elections, reflecting her belief that leadership should be driven by people, solutions, and results—not party labels. She believes protecting public safety is a commitment owed to every Arizonan. Personal: Angela is happily remarried and enjoys spending time with her family, including her six children and newest grandchild. Through years of international travel and government missions, she worked with diverse communities, including Spanish-speaking populations, strengthening her ability to connect across cultures. In 2008, her late husband was killed during a mountain rescue in Sedona while saving the lives of two others. His sacrifice continues to inspire her lifelong commitment to public service.
A14: John Giles (Hobbs) | B14: Independent | C14: Lieutenant Governor | E14: Statewide | G14: 22 | H14: 199 | I14: 0 | J14: Human | K14: =IF(I14="","no statement",IF(I14>0.5,"Yes","No")) -> No | L14: John Giles, a former Republican and now Independent, is running alongside Katie Hobbs to continue delivering real results by setting partisan politics aside and putting Arizona first. They believe our challenges are not Democrat or Republican issues – they’re Arizona issues that deserve Arizona solutions. Together, they will fight to bring down costs that keep rising because of Washington’s reckless policies. As governor, Katie has cut taxes each year for middle-class families, small businesses, and veterans. She repealed the tax on rent and cut red tape to make housing more affordable. While Washington politicians have raised healthcare costs and slashed coverage, Katie eliminated medical debt for nearly 700,000 Arizonans and lowered prescription drug costs by up to 80%. She stood up to her own party and the federal government to secure Arizona’s water and canceled leases allowing a Saudi-owned corporation to pump Arizona’s groundwater unchecked. She’s worked with law enforcement to seize over 18 million fentanyl pills, fight human trafficking, and combat cartels throughout Arizona. John and Katie share the same approach to leadership: put Arizona first, find common ground, and deliver results. Together, they’ll lower costs, protect our freedoms, keep communities safe, and create opportunity for every Arizonan.
A15: Lisa Castillo (Lombardo) | B15: Green | C15: Lieutenant Governor | E15: Statewide | G15: 22 | H15: 200 | I15: 1 | J15: AI | K15: =IF(I15="","no statement",IF(I15>0.5,"Yes","No")) -> Yes | L15: I am running for Lieutenant Governor alongside Risa Lombardo because Arizona families deserve leadership grounded in compassion, honesty, and common sense. Too many people struggle to afford housing, healthcare, education, food, and other necessities while feeling that government no longer listens to them. I will advocate for practical, humane solutions to homelessness that provide immediate assistance while addressing the causes of housing instability. I will support stronger mental-health services, including accessible treatment, crisis intervention, community programs, and stable housing. These investments can save lives, strengthen families, and make our communities safer. As a small-business owner, wife, mother, and Arizona resident since 2010, I understand the pressures families face and the importance of responsible decisions. I support the Green Party values of environmental responsibility, social justice, grassroots democracy, peace, and respect for diversity. Public service begins with listening. I will work with Arizonans from every background, treat people with dignity, and seek solutions that improve everyday life. I will put people, community well-being, and Arizona’s long-term future ahead of political games. Together, we can build an Arizona where opportunity is shared, communities are healthy, government is accountable, and every person has a fair chance to create a secure and hopeful future.
A16: Sine Kerr (Biggs) | B16: Republican | C16: Lieutenant Governor | E16: Statewide | G16: 23 | H16: 92 | I16: 0 | J16: Human | K16: =IF(I16="","no statement",IF(I16>0.5,"Yes","No")) -> No | L16: Arizona is a great state, one where my husband Bill and I raised our family and built a business. But under Katie Hobbs, the Arizona we know has come under attack. She’s raised costs, made life more difficult; and threatened the livelihood of rural Arizonans. As the Lt. Governor for Andy Biggs, I’ll make sure every Arizonan has a voice no matter where they live and how they make a living. The Biggs/Kerr ticket will put more money in your pocket, keep our state safe, and Restore the American Dream in Arizona.
A17: Adrian Fontes | B17: Democratic | C17: Secretary Of State | E17: Statewide | G17: 24 | H17: 196 | I17: 0 | J17: Human | K17: =IF(I17="","no statement",IF(I17>0.5,"Yes","No")) -> No | L17: As Secretary of State, I’ve delivered on key promises to strengthen election integrity, ensure voter access, improve business services, and promote transparency. In everything I do, my goal is to protect your vote. These efforts include launching a statewide ballot tracking system that allows voters to receive text and email updates when their ballots are sent and received. I have fought to protect your private data and vote-by-mail because nobody should have to stand in long lines in the heat to cast their vote. Ahead of the 2024 election, I hosted statewide tabletop exercises with election officials, law enforcement, and cybersecurity experts to prepare for potential threats, including emerging challenges like deepfakes and content authentication. To combat misinformation, I established the Artificial Intelligence and Election Security Advisory Committee, bringing together leaders from academia, business, and technology to assess risks and identify opportunities. In 2025, I received a Clearie Award from the U.S. Election Assistance Commission for the third consecutive year, honoring innovation and excellence in election administration. Importantly, I successfully oversaw the peaceful administration and certification of the 2024 election, reinforcing trust in Arizona’s democratic process. I would be honored to earn your vote. Thank you.
A18: Alexander Kolodin | B18: Republican | C18: Secretary Of State | E18: Statewide | G18: 25 | H18: 199 | I18: 0 | J18: Human | K18: =IF(I18="","no statement",IF(I18>0.5,"Yes","No")) -> No | L18: As Secretary of State, my sole focus will be on serving all voters, regardless of political affiliation, and administering elections that are secure, transparent, honest, and follow the law, while delivering fast results that all Arizonans can have confidence in on election night. I’ve been fighting for Arizonans’ civil liberties, including the right to free and fair elections, for well over a decade. As an experienced election attorney, I’ve successfully challenged my opponent Adrian Fontes’ numerous and repeated violations of the law in court. As a member of the Arizona House of Representatives, I’ve been the state’s most successful election policy-focused legislator — achieving broad bipartisan support for some of the most important election laws in state history. I’ve fought to protect the voting rights of military members, veterans, the disabled, rural voters, and voters from every Party, income level, race, gender and age. The reality is that the process of administering elections shouldn’t be about right vs. left or rich vs. poor. Election administration is about following the law, running world class elections, and delivering fast results that voters can trust. I’m Alex Kolodin and I’m humbly asking for your vote to be Arizona’s next Secretary of State.
A19: Duwayne Collier | B19: Green | C19: Secretary Of State | E19: Statewide | G19: 24 | H19: 143 | I19: 0 | J19: Human | K19: =IF(I19="","no statement",IF(I19>0.5,"Yes","No")) -> No | L19: Duwayne Collier is the Green Party nominee for Secretary of State. For too long our elections have been regulated by the two party system for their own gain. As the Secretary of State for Arizona, Duwayne Collier will work to end the two party monopoly by pushing for ranked-choice voting, open debates, easier ballot access, public financing, election transparency, and voter access. Democracy should not belong to the highest bidder, or billionaires’ ruling influence. Democracy belongs to the voters. As a representative of the people, Collier will fight to ensure that every vote is counted, results are fast and accurate, and that your vote is heard! Collier will work for a system that encourages strong third parties and ends special interests and corporate influence over elections. Duwayne Collier would be honored to have your vote to reform Arizona and represent you, the people!
... A25: Teresa Leyba Ruiz | B25: Democratic | C25: Superintendent Of Public Instruction | E25: Statewide | G25: 28 | H25: 201 | I25: 0 | J25: Human | K25: =IF(I25="","no statement",IF(I25>0.5,"Yes","No")) -> No | L25: Dr. Ruiz is proud to be the only educator running for Superintendent and believes a teacher — not a career politician — should oversee Arizona’s public schools. Her priorities include increasing transparency and accountability, protecting taxpayer dollars, stabilizing the teacher workforce, upholding high academic standards with strong support systems, and expanding career and post-secondary training opportunities. As a former community college president, Terry has managed operating budgets larger than the Arizona Department of Education with transparency and fiscal responsibility. She will bring that same leadership to the office by strengthening oversight of the ESA program, ending the automatic approval of purchases, implementing automated solutions, and creating a public transparency portal so taxpayers can see how funds are spent. After listening to educators in all 15 Arizona counties, Terry plans on supporting her fellow teachers through professional development, mentorship, and advocacy for competitive pay. As Superintendent, she will expand opportunities for all students in the K-12 system from early literacy and math interventions, to increased access to career and technical education and dual enrollment pathways. Dr. Ruiz believes that when our schools succeed, our state succeeds, and will focus on real results for our students — not political agendas and empty rhetoric.
A26: Quang Huu Nguyen | B26: Republican | C26: State Representative - District 1 | D26: 1 | E26: Legislative | F26: House | G26: 33 | H26: 189 | I26: 0 | J26: Human | K26: =IF(I26="","no statement",IF(I26>0.5,"Yes","No")) -> No | L26: I ran for office as a Constitutional Conservative, you trusted and elected me, and I’ve gone to work each day and KEPT MY WORD! That means real election integrity measures, secure borders (finishing that wall), criminalizing fentanyl dealers, fighting for affordability, medical freedom, safe neighborhoods, improved highways and transportation (improving I-17), long-term water security, and personal liberty. I have a 100% pro- gun, pro-Constitution, pro-life, pro-school choice, and pro-Arizona voting record. I’ve worked closely with Representative Selina Bliss and our district is home to Arizona’s most reliably conservative State Reps. We are again being challenged from our left by the same candidate you rejected last time, but that’s okay. Voters should have choices, and we’re going to keep voting for conservative ideals no matter who runs against us. You know me, and you know the love I have for my country, my state, and everyone who calls it home. If you want a proven America First team, then I ask you to cast your TWO State House votes for Nguyen AND Bliss. On behalf of my wonderful wife and kids, THANK YOU! And may God continue to bless America.
A27: Sandy Zalecki | B27: Democratic | C27: State Representative - District 1 | D27: 1 | E27: Legislative | F27: House | G27: 34 | H27: 198 | I27: 0 | J27: Human | K27: =IF(I27="","no statement",IF(I27>0.5,"Yes","No")) -> No | L27: I have never wanted to be a politician, but I found out that being in politics is one of the best ways to help others if it's done properly. I'm not good a making big promises that I can't keep. I don't like to lie. If I were elected there are four things that I would work to change. One would be to require every state candidate to run clean elections. It would make it more fair and take some of the dirty money out of politics. Second, water. We haven't had any water legislation since the 1980 Ground Water Act. It needs to be updated to insure abundant water for our future. Third, affordability. We have an affordability crisis in Arizona that our current legislature refuses to acknowledge. Fourth, education. We are 49th in spending on education. We have 100 million dollars in fraud because of ESA vouchers. Our children deserve better from us. They are our future. According to Markers for Democracy "Arizona's state legislature is one of the most reactionary and harmful in the nation." Something needs to change and I would like to be one of the ones that helps make the needed changes.
A28: Selina Bliss | B28: Republican | C28: State Representative - District 1 | D28: 1 | E28: Legislative | F28: House | G28: 33 | H28: 200 | I28: 0 | J28: Human | K28: =IF(I28="","no statement",IF(I28>0.5,"Yes","No")) -> No | L28: As I wrap up my second term in office, I am happy to report I’ve kept my promises and built a strong conservative record on issues that matter to Arizona voters. Working with my seatmate, Representative Quang Nguyen, I prioritized efforts to boost the Arizona economy and fight inflation, secure our border and enforce our laws, and restore integrity to our election process. I have demonstrated a 100% pro-2nd Amendment record, led to secure our water future, fought to protect life, and prioritized both veterans and first responders. I also used my background as a nurse and educator to lead on healthcare issues and support medical freedom, while reducing fraud, waste, and abuse, and working to improve our schools and universities. I’ve lived in this District since 1971 and have been involved with a variety of political, civic, and charitable organizations. I’m committed to public service and am grateful for the trust you have placed in me. You have TWO votes for the State House, and I hope I can count on you to cast one vote for me so I can return to work alongside Representative Quang Nguyen to prioritize LD1 and keep Arizona great! I appreciate your support!
A29: Christine Ellen Dargon | B29: Democratic | C29: State Senator - District 1 | D29: 1 | E29: Legislative | F29: Senate | G29: 32 | H29: 201 | I29: 1 | J29: AI | K29: =IF(I29="","no statement",IF(I29>0.5,"Yes","No")) -> Yes | L29: Legislative District 1 deserves a senator who actually works for the people who live here and right now, we don't have one. Our current senator parachuted into this district after losing a statewide race and has spent his time denying elections, banning abortion with no exceptions for rape or incest, chasing national headlines while LD1's real problems go unaddressed. He does not work for you - I will! Our wells are failing as aquifers are drawn down by unregulated corporate pumping. Our schools are among the most underfunded in the nation. Families are driving two hours for basic medical care. These are not unsolvable problems. I will fight for groundwater protections that put LD1 families before corporate extraction interests. I will fight to fully fund our public schools and pay teachers what they deserve. I will fight to expand rural healthcare access so that a medical emergency doesn't also become a financial one or a tragedy because help is hours away. I will fight for zoning reforms that remove unnecessary barriers to workforce and affordable housing development, state investment in rural housing infrastructure, and tenant protections that keep working families stably housed. Solutions over stunts. Community over career. No special interests.
A30: Mark Finchem | B30: Republican | C30: State Senator - District 1 | D30: 1 | E30: Legislative | F30: Senate | G30: 32 | J30: no statement | K30: =IF(I30="","no statement",IF(I30>0.5,"Yes","No")) -> no statement | L30: (none submitted)
A31: Justin Wilmeth | B31: Republican | C31: State Representative - District 2 | D31: 2 | E31: Legislative | F31: House | G31: 37 | H31: 200 | I31: 0 | J31: Human | K31: =IF(I31="","no statement",IF(I31>0.5,"Yes","No")) -> No | L31: Howdy everyone! I have had the honor of serving in the Arizona House of Representatives for the past six years. I've spent that time fighting against overreaching COVID mandates, lowering taxes, eliminating burdensome regulations, improving housing affordability and, yes, making Pluto the State Planet. I've been chairman of the House Commerce Committee, where I focused on improving economic development and bringing more jobs to the district. Currently, I serve as the chairman of the House Artificial Intelligence & Innovation Committee, where I am helping guide the way on the new digital policy frontier. I want to help this technology be more beneficial to you! I've spent my entire career in public policy. I've worked a combined 12 years at two different state legislatures, including here in Arizona, where I was a policy staffer for the Republican Caucus. I also worked at Americans for Prosperity, a Conservative entity focused on lowering taxes, regulations and shrinking government wherever possible. I'm very proud to say I'm an effective Legislator for our district and I understand how to get the job done. I want to ensure Arizona continues to be friendly for free markets and individual liberties! I look forward to earning your support.
A32: Paul Carver | B32: Republican | C32: State Representative - District 2 | D32: 2 | E32: Legislative | F32: House | G32: 36 | H32: 195 | I32: 1 | J32: AI | K32: =IF(I32="","no statement",IF(I32>0.5,"Yes","No")) -> Yes | L32: As President of the Deer Valley Unified School District Governing Board, I have spent my tenure championing transparency, parental rights, and fiscal accountability in public education. Now, I am asking for your vote to bring that same principled, results-oriented leadership to the Arizona House of Representatives for Legislative District 2. Our community faces vital challenges that demand practical, battle-tested solutions. As a Marine Corps veteran, business analyst, and father, I understand the direct impact of state policy on our families, local businesses, and neighborhood schools. My platform centers on four core pillars: protecting taxpayer dollars through strict fiscal discipline, empowering parents to make the best educational choices for their children, strengthening public safety by fully supporting law enforcement, and addressing critical water concerns to secure the future of the Valley. After earning my place on the general election ballot through a successful primary write-in effort, I am deeply honored by the grassroots support of our community. Legislative District 2 deserves a representative who listens, operates with integrity, and delivers accountable governance. I promise to work tirelessly at the State Capitol to safeguard your freedom and build a stronger Arizona. I respectfully ask for your vote.
A33: Stephanie Simacek | B33: Democratic | C33: State Representative - District 2 | D33: 2 | E33: Legislative | F33: House | G33: 36 | H33: 180 | I33: 0 | J33: Human | K33: =IF(I33="","no statement",IF(I33>0.5,"Yes","No")) -> No | L33: I am a mom, public school teacher, Deer Valley Unified School District governing board member, and an Arizona State House Representative. I first ran for office to strengthen public education, address our water crisis, and tackle rising costs, including childcare, healthcare, and housing. Since my election in 2024, I have had the honor and privilege to fight for these issues on behalf of Arizona’s second legislative district. These are not partisan issues; they affect us all, regardless of our political affiliation. As a public school teacher, I saw firsthand the positive impact of diverse teaching methods, dedicated staff, and engaged parents. As a mother, I’ve felt how hard rising costs in healthcare, housing, childcare, food, and utilities have hit Arizona families. As an Arizonan, I know we must act fast to ensure that future generations get to enjoy this great state we all know and love. I am seeking reelection this year because our work is far from finished. There is still so much we can do, and I remain committed to continuing that work on behalf of my neighbors.
A34: Amelia Gallitano | B34: Democratic | C34: State Senator - District 2 | D34: 2 | E34: Legislative | F34: Senate | G34: 35 | H34: 190 | I34: 0 | J34: Human | K34: =IF(I34="","no statement",IF(I34>0.5,"Yes","No")) -> No | L34: My name is Amelia Gallitano. I’m a doctor, neuroscientist, professor, and mom. I moved here 19 years ago with my two sons to be a professor at the University of Arizona College of Medicine in Phoenix, and I’ve been educating new doctors ever since. I also cared for veterans with PTSD at the Phoenix VA for years. It does not take a PhD in neuroscience to see that something is very wrong in our legislature. Lawmakers are giving tax breaks to private plane owners while everyday Arizonans struggle to make ends meet. They are giving away a billion dollars with no accountability to private school vouchers while attacking the public schools that 90% of Arizona families choose. They want to take away Vote by Mail, which more than 75% of voters rely on. I’ve spent my life in public service, and I’m stepping up to work for everyday Arizonans. I will make healthcare more affordable, support our public schools and teachers, and stop corporations from driving up housing and energy costs. It’s time for a state senator focused on people, not corporate profits. I would be honored to represent you.
A35: Shawnna Bolick | B35: Republican | C35: State Senator - District 2 | D35: 2 | E35: Legislative | F35: Senate | G35: 35 | H35: 152 | I35: 0 | J35: Human | K35: =IF(I35="","no statement",IF(I35>0.5,"Yes","No")) -> No | L35: Actions and accomplishments speak louder than empty promises. Since 2019, I have represented you with a common-sense voice at the State Capitol. I have supported legislation to secure our border, reduce taxes, and improve affordability. I led the fight to make housing more affordable, lower inflation on our food and housing, and voted to pass one of the largest tax cuts in state history. I am proud of my votes to invest in our schools and teachers, fight drug trafficking and fentanyl, advance consumer protection, and end child sex trafficking. As a mom, tackling public safety issues is personal to me - and critical for our community. I will continue to champion commonsense solutions to the challenges facing our community, from standing up for veterans to protecting our water supply. Please visit my website at www.BolickforArizona.com to learn more or ask questions, and I humbly ask for your vote. Thank you! Shawnna
A36: Cody Reim | B36: Republican | C36: State Representative - District 3 | D36: 3 | E36: Legislative | F36: House | G36: 40 | J36: no statement | K36: =IF(I36="","no statement",IF(I36>0.5,"Yes","No")) -> no statement | L36: (none submitted)
A37: George Khalaf | B37: Republican | C37: State Representative - District 3 | D37: 3 | E37: Legislative | F37: House | G37: 39 | H37: 199 | I37: 0 | J37: Human | K37: =IF(I37="","no statement",IF(I37>0.5,"Yes","No")) -> No | L37: I’m George Khalaf and I’m proud to be running to represent LD3 in the Arizona House. We need leaders to cast and deliver a conservative vision for our state, and that’s why I stepped up. First and foremost, I’m a Christian, husband to Briana, father to three sons and an America-First conservative. My parents immigrated legally to the US from Lebanon to give their children a chance to experience freedom and the American dream. I wake up every day grateful to live in the greatest country in the world. I’ll focus on growing a pro-family economy through low taxes, more efficient government, and pro-small business policies. I’ll support strong families by defending parents’ rights, opposing woke indoctrination and making education work for parents and students. Safe communities start with a secure border. I’ll back our men and women in law enforcement and vote for policies that keep criminals off our streets. I’ll defend our Constitutional Freedoms of life, free speech, religious freedom and the 2nd Amendment. I’ll fight for free and fair elections with full transparency. As your representative, I'll answer to the people and my principles–not special interests. Together, we’ll make Arizona’s next 10 years free and prosperous.
A38: John Skirbst | B38: No Labels | C38: State Representative - District 3 | D38: 3 | E38: Legislative | F38: House | G38: 40 | H38: 157 | I38: 0 | J38: Human | K38: =IF(I38="","no statement",IF(I38>0.5,"Yes","No")) -> No | L38: A moderate and independent voice. Fiscal conservative and liberal leaning on social issues. A problem solver that can place sound judgement above party politics. Helping to shape and pass bipartisan laws will be a priority. Reinventing the economy for the 21st century and lowering costs for Arizona families. This includes repairing a broken health care system. Ensure a sustainable water supply in Arizona. Solutions include upgrading infrastructure and improving water management and conservation strategies. Securing Arizona’s border and fixing a broken immigration process. This includes investments in technology, staffing, and barriers where they make sense. You have a second amendment right to bear arms. With rights though must come responsibilities. Common sense gun laws can help keep our communities safe. I respect your right, if you oppose abortion. So please respect each woman’s right to choose what is best for her own body and unique circumstances. Please cast one of your two votes for an independent candidate.
A39: Julie Gable | B39: Democratic | C39: State Representative - District 3 | D39: 3 | E39: Legislative | F39: House | G39: 39 | H39: 206 | I39: 1 | J39: AI | K39: =IF(I39="","no statement",IF(I39>0.5,"Yes","No")) -> Yes | L39: I raised my family here. I built a career here. And I've watched our state's challenges become personal ones. As an executive, I led teams through hard decisions with high stakes and real, human consequences. Most recently, as the CEO of a healthcare company with more than 250 employees across multiple campuses, I managed a tight budget that required significant cost-cutting efforts. I led our team through a 30% budget reduction without cutting quality of care. Now, I want to put my real-world experience and steady judgment to work for the community I love. I'm running because Arizona deserves leaders who solve problems instead of just talking about them. That starts with making healthcare more affordable by holding insurance companies accountable, reducing unnecessary administrative burden on healthcare providers, and targeting fraud, waste, and abuse. It also means ensuring technology serves people responsibly, strengthening our public schools, and securing our water future for generations to come. I'm not accepting money from big donors or special interests. As a Clean Elections candidate, I am only accountable to the community I serve. I'm not a career politician. I'm a mom, a business owner, and your neighbor. I'm proven, principled, and pragmatic. And I'd be honored to earn your vote.
A40: Richard "Rick" Robert Spargo | B40: Democratic | C40: State Representative - District 3 | D40: 3 | E40: Legislative | F40: House | G40: 40 | H40: 171 | I40: 1 | J40: AI | K40: =IF(I40="","no statement",IF(I40>0.5,"Yes","No")) -> Yes | L40: I stand for Common Sense and Moderation. You won’t find any extremism here. Our District and Arizona deserve leadership grounded in practicality, not partisanship. The challenges we face are water scarcity, underfunded public schools and the rising cost of living. I call for cooperation and real solutions that bring people together, not drive us apart. Securing our water future must be a top priority. We must invest in conservation, expand water reuse, and protect our supplies from overuse and speculation. Arizona can grow while preserving sustainability. Strong public education is the foundation of opportunity. I’ll work to ensure every classroom has the teachers, resources and support needed to help students thrive. Affordability matters. From housing to energy to healthcare. I will champion for policies that keep Arizona livable for working families, small business owners and seniors alike. I’m running to restore moderation and respect to our politics, focusing on results over ideology, collaboration over conflict, and responsibility over division. Together, we can build a balanced, forward-looking future rooted in common sense.
A41: Jeffrey Fortney | B41: Democratic | C41: State Senator - District 3 | D41: 3 | E41: Legislative | F41: Senate | G41: 38 | H41: 197 | I41: 0 | J41: Human | K41: =IF(I41="","no statement",IF(I41>0.5,"Yes","No")) -> No | L41: I am running for State Senate in Legislative District 3 for several reasons. Too many families in Legislative District 3 are feeling the economic impact of decisions being made federally and rubber stamped locally. Many are trying to balance working (sometimes multiple jobs), while paying for child care, medicine and other increasing costly expenses. These people are feeling the effects of national economic decisions locally, while local legislators rubber stamp policies that are driving up these costs. Families are effectively being billed an average of $2,300 due to illegal tariffs. Grocery prices continue to climb while local legislators are doing nothing to support working families. They are in fact making it even more difficult for working families to feed and support their children. I will work tirelessly to support working families in Arizona. In addition, I have a long record of protecting, supporting, and respecting vulnerable children while many local legislators bully these same children while supporting and protecting powerful people who are taking advantage of children. Voters are looking for leadership that prioritizes lowering everyday costs and holding decision-makers accountable for policies that hurt American families. I want to be their advocate at the state capitol.
A42: John Kavanagh | B42: Republican | C42: State Senator - District 3 | D42: 3 | E42: Legislative | F42: Senate | G42: 38 | H42: 174 | I42: 1 | J42: AI | K42: =IF(I42="","no statement",IF(I42>0.5,"Yes","No")) -> Yes | L42: I am running for re-election because Arizona deserves experienced, steady leadership that delivers results. Throughout my legislative service, I have worked to protect our communities, strengthen public safety, and ensure government remains accountable to the people. With a background in law enforcement and years of legislative experience, I understand the challenges facing our state and the practical solutions needed to address them. I have fought to secure Arizona’s borders, support law enforcement, and keep our neighborhoods safe. I believe in responsible government, keeping taxes low, controlling spending, and reducing unnecessary regulations so families and businesses can thrive. Arizona’s continued success depends on affordability and economic growth that protects taxpayers. I am also committed to defending Arizona’s water resources, defending school choice, and keeping "woke" ideologies out of our schools - classrooms should focus on academics, not politics. Additionally, I have supported improvements in transportation infrastructure and investments in education. There is still important work to be done. I ask for your support to continue delivering commonsense leadership to keep Arizona safe, prosperous, and free.
A43: Karen Gresham | B43: Democratic | C43: State Representative - District 4 | D43: 4 | E43: Legislative | F43: House | G43: 43 | H43: 182 | I43: 0 | J43: Human | K43: =IF(I43="","no statement",IF(I43>0.5,"Yes","No")) -> No | L43: As a school board member, she oversees multimillion-dollar budgets, advocates for responsible fiscal management, and supports educators and staff. This gives her the skills and experience needed to carefully evaluate policy for their impact on the public while collaborating with fellow board members. If elected to the legislature, Karen will work for public education funding, fiscal accountability, and an affordable Arizona with a budget that works for everyone. I’m a third-generation Arizonan who believes our state works best when we invest in opportunity and manage our finances responsibly. As a former CPA and graduate of Arizona State University, I understand how to build balanced budgets and analyze data to make smart decisions. I am currently serving my second term as an elected member of the Madison Elementary School District governing board. I know what Arizona schools, teachers, and students need. I am running to strengthen public education, restore fiscal accountability, and ensure an affordable Arizona with a budget that works for everyone. I look forward to representing LD4 in the State House and working on sensible solutions to the challenges we face.
A44: Matt Gress | B44: Republican | C44: State Representative - District 4 | D44: 4 | E44: Legislative | F44: House | G44: 43 | H44: 197 | I44: 0.58558559 | J44: Mixed | K44: =IF(I44="","no statement",IF(I44>0.5,"Yes","No")) -> Yes | L44: Matt Gress represents District 4 in the Arizona House of Representatives, delivering real results for Arizona families. A conservative Republican, Matt believes in securing our border, cutting taxes, balancing budgets, and protecting individual liberty. At the Capitol, Matt has proven he can get things done. He authored and passed the most comprehensive school safety legislation in decades, led the effort to enact Preston’s Law to crack down on teen mob violence, and secured funding to support law enforcement families and strengthen recruitment. He has worked to increase teacher pay, lower the cost of living, and keep Arizona free, competitive, and open for opportunity. Matt’s story is rooted in hard work. Raised by a single mom in a small town in Oklahoma, he worked his way through college by driving school buses and became the first in his family to earn a degree. He later taught high school and served on a local school board, fighting to keep schools open during COVID-19 and expand educational freedom. Before the Legislature, Matt served as Arizona’s budget director, helping deliver the largest tax cut in state history. Matt Gress is a proven conservative fighting to keep Arizona on the right track.
A45: Pamela Carter | B45: Republican | C45: State Representative - District 4 | D45: 4 | E45: Legislative | F45: House | G45: 42 | H45: 188 | I45: 1 | J45: AI | K45: =IF(I45="","no statement",IF(I45>0.5,"Yes","No")) -> Yes | L45: Pamela Carter — Arizona House of Representatives, Legislative District 4 Republican | Candidate for Reelection My name is Pamela Carter. I'm a fourth-generation Arizonan, small business owner, and proud representative of the community I've called home my entire life. In my first term, I was appointed Vice Chair of the Public Safety and Law Enforcement Committee, a leadership role rarely given to a freshman, and I worked to earn it. I passed legislation protecting deployed military service members from unfair vehicle taxes, championed Arizona's nuclear energy future, and stood against powerful corporate interests to defend Scottsdale's right to vote on its own development decisions. This session, I sponsored Cade's Law to hold accountable those who encourage minors toward suicide online, legislation targeting sexual extortion of minors, and bills protecting Arizona homebuyers and expanding access to our state's critical minerals. My priorities haven't changed: safe communities, strong law enforcement, parental rights in education, local control, low taxes, and secure elections. LD4 deserves a representative who shows up, listens, and puts Arizona first. That is the commitment I make to you every day. I humbly ask for your vote. pamelacarter.com
...

Sheet Summary & charts
A1: Summary Figures
A3: Overall
A4: Statements scored | B4: =COUNT(Candidates!I2:I209) -> 198
A5: Flagged (AI score > 0.50) | B5: =COUNTIF(Candidates!I2:I209,">0.5") -> 70
A6: Flagged rate | B6: =B5/B4 -> 0.35353535
A7: Scored exactly 0.00 | B7: =COUNTIF(Candidates!I2:I209,0) -> 121
A8: Scored 0.95 or higher | B8: =COUNTIF(Candidates!I2:I209,">=0.95") -> 63
A9: Candidates with no statement | B9: =COUNTIF(Candidates!J2:J209,"no statement") -> 10
A13: By race type
B14: Statements | C14: Flagged | D14: Rate
A15: Statewide | B15: =COUNTIFS(Candidates!$E$2:$E$209,$A15,Candidates!$I$2:$I$209,">=0") -> 23 | C15: =COUNTIFS(Candidates!$E$2:$E$209,$A15,Candidates!$I$2:$I$209,">0.5") -> 7 | D15: =IFERROR(C15/B15,0) -> 0.30434783
A16: Legislative | B16: =COUNTIFS(Candidates!$E$2:$E$209,$A16,Candidates!$I$2:$I$209,">=0") -> 155 | C16: =COUNTIFS(Candidates!$E$2:$E$209,$A16,Candidates!$I$2:$I$209,">0.5") -> 49 | D16: =IFERROR(C16/B16,0) -> 0.31612903
A17: County | B17: =COUNTIFS(Candidates!$E$2:$E$209,$A17,Candidates!$I$2:$I$209,">=0") -> 20 | C17: =COUNTIFS(Candidates!$E$2:$E$209,$A17,Candidates!$I$2:$I$209,">0.5") -> 14 | D17: =IFERROR(C17/B17,0) -> 0.7
A20: By party
B21: Statements | C21: Flagged | D21: Rate
A22: Democratic | B22: =COUNTIFS(Candidates!$B$2:$B$209,$A22,Candidates!$I$2:$I$209,">=0") -> 92 | C22: =COUNTIFS(Candidates!$B$2:$B$209,$A22,Candidates!$I$2:$I$209,">0.5") -> 36 | D22: =IFERROR(C22/B22,0) -> 0.39130435
A23: Republican | B23: =COUNTIFS(Candidates!$B$2:$B$209,$A23,Candidates!$I$2:$I$209,">=0") -> 91 | C23: =COUNTIFS(Candidates!$B$2:$B$209,$A23,Candidates!$I$2:$I$209,">0.5") -> 28 | D23: =IFERROR(C23/B23,0) -> 0.30769231
A24: Green | B24: =COUNTIFS(Candidates!$B$2:$B$209,$A24,Candidates!$I$2:$I$209,">=0") -> 6 | C24: =COUNTIFS(Candidates!$B$2:$B$209,$A24,Candidates!$I$2:$I$209,">0.5") -> 2 | D24: =IFERROR(C24/B24,0) -> 0.33333333
A25: Independent | B25: =COUNTIFS(Candidates!$B$2:$B$209,$A25,Candidates!$I$2:$I$209,">=0") -> 4 | C25: =COUNTIFS(Candidates!$B$2:$B$209,$A25,Candidates!$I$2:$I$209,">0.5") -> 1 | D25: =IFERROR(C25/B25,0) -> 0.25
A26: No Labels | B26: =COUNTIFS(Candidates!$B$2:$B$209,$A26,Candidates!$I$2:$I$209,">=0") -> 5 | C26: =COUNTIFS(Candidates!$B$2:$B$209,$A26,Candidates!$I$2:$I$209,">0.5") -> 3 | D26: =IFERROR(C26/B26,0) -> 0.6
A30: Distribution of AI scores
A31: Bin | B31: Statements
A32: 0%-5% | B32: =COUNTIFS(Candidates!$I$2:$I$209,">=0.0",Candidates!$I$2:$I$209,"<0.05") -> 121
A33: 5%-10% | B33: =COUNTIFS(Candidates!$I$2:$I$209,">=0.05",Candidates!$I$2:$I$209,"<0.1") -> 0
A34: 10%-15% | B34: =COUNTIFS(Candidates!$I$2:$I$209,">=0.1",Candidates!$I$2:$I$209,"<0.15000000000000002") -> 0
A35: 15%-20% | B35: =COUNTIFS(Candidates!$I$2:$I$209,">=0.15000000000000002",Candidates!$I$2:$I$209,"<0.2") -> 0
A36: 20%-25% | B36: =COUNTIFS(Candidates!$I$2:$I$209,">=0.2",Candidates!$I$2:$I$209,"<0.25") -> 1
A37: 25%-30% | B37: =COUNTIFS(Candidates!$I$2:$I$209,">=0.25",Candidates!$I$2:$I$209,"<0.30000000000000004") -> 1
A38: 30%-35% | B38: =COUNTIFS(Candidates!$I$2:$I$209,">=0.30000000000000004",Candidates!$I$2:$I$209,"<0.35000000000000003") -> 1
A39: 35%-40% | B39: =COUNTIFS(Candidates!$I$2:$I$209,">=0.35000000000000003",Candidates!$I$2:$I$209,"<0.4") -> 3
A40: 40%-45% | B40: =COUNTIFS(Candidates!$I$2:$I$209,">=0.4",Candidates!$I$2:$I$209,"<0.45") -> 0
A41: 45%-50% | B41: =COUNTIFS(Candidates!$I$2:$I$209,">=0.45",Candidates!$I$2:$I$209,"<0.5") -> 1
A42: 50%-55% | B42: =COUNTIFS(Candidates!$I$2:$I$209,">=0.5",Candidates!$I$2:$I$209,"<0.55") -> 1
A43: 55%-60% | B43: =COUNTIFS(Candidates!$I$2:$I$209,">=0.55",Candidates!$I$2:$I$209,"<0.6000000000000001") -> 2
A44: 60%-65% | B44: =COUNTIFS(Candidates!$I$2:$I$209,">=0.6000000000000001",Candidates!$I$2:$I$209,"<0.65") -> 0
A45: 65%-70% | B45: =COUNTIFS(Candidates!$I$2:$I$209,">=0.65",Candidates!$I$2:$I$209,"<0.7000000000000001") -> 3
A46: 70%-75% | B46: =COUNTIFS(Candidates!$I$2:$I$209,">=0.7000000000000001",Candidates!$I$2:$I$209,"<0.75") -> 0
A47: 75%-80% | B47: =COUNTIFS(Candidates!$I$2:$I$209,">=0.75",Candidates!$I$2:$I$209,"<0.8") -> 0
A48: 80%-85% | B48: =COUNTIFS(Candidates!$I$2:$I$209,">=0.8",Candidates!$I$2:$I$209,"<0.8500000000000001") -> 1
A49: 85%-90% | B49: =COUNTIFS(Candidates!$I$2:$I$209,">=0.8500000000000001",Candidates!$I$2:$I$209,"<0.9") -> 0
...
